# Manejo de errores

Prácticamente cualquier objeto puede ser lanzado en JavaScript. Sin embargo, no todos los objetos lanzados son creados igual. Mientras que es bastante común para lanzar números o strings como errores, frecuentemente son más efectivos utilizar uno de los tipos de excepciones específicamente creados para este propósito.

`Puedes lanzar excepciones usando la sentencia throw y manejarlas usando las sentencias try...catch.`

## Ejemplos

```js
throw "Error2";   // Tipo string
throw 42;         // Tipo número
throw true;       // Tipo booleano
throw {toString: function() { return "¡Soy un objeto!"; } };
```

## Bloque Try

La sentencia try...catch marca un bloque de instrucciones a intentar que pueden causar alguna excepción, y declarar una o más respuestas en caso de que una excepción sea arrojada. Si una excepción es arrojada, la sentencia try...catch se encarga de atraparla.

```js
function getMonthName (mo) {
  mo = mo-1; // Ajusta el índice del arreglo para el arreglo de meses (1=Jan, 12=Dec)
  var months = ["Jan","Feb","Mar","Apr","May","Jun","Jul",
                "Aug","Sep","Oct","Nov","Dec"];
  if (months[mo] != null) {
    return months[mo];
  } else {
    throw "InvalidMonthNo"; //Arroja la palabra "InvalidMonthNo" al ocurrir una excepción
  }
}

try { // instrucciones a probar
  monthName = getMonthName(myMonth); // La función puede arrojar una excepción
}
catch (e) {
  monthName = "unknown";
  logMyErrors(e); // Pasa el objeto de la excepción a un manejador de errores
}
```

## Bloque catch

Un bloque catch es usado para manejar todas las excepciones que pueden ser generadas en el bloque try.

```js
catch (catchID) {
  instrucciones
}
```

## Bloque finally

El bloque finally contiene instrucciones para ejecutar luego de la ejecución del bloque try y el bloque catch pero antes de las instrucciones ubicadas luego de la sentencia try...catch. El bloque finally se ejecuta cuando se haya arrojado o no una excepción. Si una excepción es arrojada, las instrucciones en el bloque finally se ejecutan incluso si no existe un bloque catch que maneje la excepción.


```js
openMyFile();
try {
  // Esto puede arrojar un error
  writeMyFile(theData);
} catch(e) {
  // Si ocurre un error es manejado
  handleError(e);
} finally {
  // Siempre cierra el recurso
  closeMyFile();
}
```

## Ejemplo completo

```js
function f() {
  try {
    console.log(0);
    throw "bogus";
  } catch(e) {
    console.log(1);
    return true; // Esta sentencia de retorno es suspendida
                 // hasta que el bloque finally esté completo
    console.log(2); // no alcanzable
  } finally {
    console.log(3);
    return false; // sobreescribe la sentencia de retorno anterior
    console.log(4); // no alcanzable
  }
  // "return false" es ejecutada ahora
  console.log(5); // no alcanzable
}
f(); // console 0, 1, 3; retorna false
```

## Otro ejemplo completo

```js
function f() {
  try {
    throw "bogus";
  } catch(e) {
    console.log('caught inner "bogus"');
    // Esta sentencia throw es suspendida hasta que
    throw e;
    // el bloque finally se termine de ejecutar
  } finally {
    // Sobreescribe la sentencia throw anterior
    return false;
  }
  // "return false" es ejecutado ahora
}

try {
  f();
} catch(e) {
  // Esta nunca es encontrada porque la sentencia throw dentro
  // del bloque catch es sobrescrita por la sentencia return
  // en el bloque finally
  console.log('caught outer "bogus"');
}

// SALIDA
// atrapado dentro de "bogus"

```